<?xml version="1.0"?>
<!-- created with Phobos 1.0.1 "Capricious Choutengan" -->
  <robot name="arm_scale">

    <link name="base_joint">
      <inertial>
        <origin xyz="0 0 0" rpy="0 0 0"/>
        <mass value="1.0"/>
        <inertia ixx="10589.11148" ixy="3.17383" ixz="-0.28477" iyy="10573.97458" iyz="1.77188" izz="242.34695"/>
      </inertial>
      <visual name="base">
        <origin xyz="0 0 0" rpy="0 0 0"/>
        <geometry>
          <mesh filename="package://model_spawner/model/arm4/meshes/dae/base_mesh.dae" scale="12.5 12.5 4.5"/>
        </geometry>
        <material name="base_material"/>
      </visual>
      <collision name="base">
        <origin xyz="0 0 -1.74435" rpy="0 0 0"/>
        <geometry>
          <cylinder radius="12.5" length="9.0"/>
        </geometry>
      </collision>
    </link>

    <link name="link_1_joint">
      <inertial>
        <origin xyz="0 0 0" rpy="0 0 0"/>
        <mass value="1.0"/>
        <inertia ixx="11897.9001" ixy="0.1" ixz="-0.15925" iyy="11892.19952" iyz="-83.18975" izz="67.30753"/>
      </inertial>
      <visual name="link_1">
        <origin xyz="0 0 0" rpy="0 0 0"/>
        <geometry>
          <mesh filename="package://model_spawner/model/arm4/meshes/dae/link_1_mesh.dae" scale="10.0 10.0 3.5"/>
        </geometry>
        <material name="link_1_material"/>
      </visual>
      <collision name="link_1">
        <origin xyz="-0.02008 -0.61999 0.72337" rpy="0 0 0"/>
        <geometry>
          <cylinder radius="10.0" length="7.10471"/>
        </geometry>
      </collision>
    </link>

    <link name="link_2_joint">
      <inertial>
        <origin xyz="0 12.49996 0" rpy="0 0 0"/>
        <mass value="1.0"/>
        <inertia ixx="1412.49023" ixy="0.57088" ixz="-0.7808" iyy="1419.77344" iyz="-2.36581" izz="133.62944"/>
      </inertial>
      <visual name="link_2">
        <origin xyz="0 12.49996 0" rpy="0 0 0"/>
        <geometry>
          <mesh filename="package://model_spawner/model/arm4/meshes/dae/link_2_mesh.dae" scale="4.0 4.0 4.0"/>
        </geometry>
        <material name="link_2_material"/>
      </visual>
      <collision name="link_2">
        <origin xyz="0 12.4999 -0.56251" rpy="1.5708 0 0"/>
        <geometry>
          <cylinder radius="4.99473" length="32.20313"/>
        </geometry>
      </collision>
    </link>

    <link name="link_3_joint">
      <inertial>
        <origin xyz="0 0 0" rpy="0 0 0"/>
        <mass value="1.0"/>
        <inertia ixx="773.92639" ixy="-0.14592" ixz="0.78848" iyy="781.10718" iyz="-0.11002" izz="130.68288"/>
      </inertial>
      <visual name="link_3">
        <origin xyz="0 2e-05 0" rpy="0 0 0"/>
        <geometry>
          <mesh filename="package://model_spawner/model/arm4/meshes/dae/link_3_mesh.dae" scale="4.0 4.0 4.0"/>
        </geometry>
        <material name="link_3_material"/>
      </visual>
      <collision name="link_3">
        <origin xyz="0 4.16669 -0.56363" rpy="1.5708 0 0"/>
        <geometry>
          <cylinder radius="4.99472" length="16.9276"/>
        </geometry>
      </collision>
    </link>

    <link name="link_4_joint">
      <inertial>
        <origin xyz="0 0 0" rpy="0 0 0"/>
        <mass value="1.0"/>
        <inertia ixx="137.33632" ixy="-0.63232" ixz="-3.725" iyy="163.16416" iyz="5.77508" izz="715.10317"/>
      </inertial>
      <visual name="link_4">
        <origin xyz="0 0 -5e-05" rpy="0 0 0"/>
        <geometry>
          <mesh filename="package://model_spawner/model/arm4/meshes/dae/link_4_mesh.dae" scale="4.0 4.0 6.25"/>
        </geometry>
        <material name="link_4_material"/>
      </visual>
      <collision name="link_4">
        <origin xyz="0 0 -0.40428" rpy="0 0 0"/>
        <geometry>
          <cylinder radius="4.0" length="8.44244"/>
        </geometry>
      </collision>
    </link>

    <link name="link_5_joint">
      <inertial>
        <origin xyz="0 3.64154 0" rpy="0 0 0"/>
        <mass value="1.0"/>
        <inertia ixx="284.06784" ixy="0.28928" ixz="0.6144" iyy="264.62717" iyz="0.04341" izz="113.16734"/>
      </inertial>
      <visual name="link_5">
        <origin xyz="0 3.6415 0" rpy="-1.5708 0 0"/>
        <geometry>
          <mesh filename="package://model_spawner/model/arm4/meshes/dae/link_5_mesh.dae" scale="4.0 4.0 4.0"/>
        </geometry>
        <material name="link_5_material"/>
      </visual>
      <collision name="link_5">
        <origin xyz="0 3.1131 0.00078" rpy="-1.5708 0 0"/>
        <geometry>
          <cylinder radius="4.0" length="5.73715"/>
        </geometry>
      </collision>
    </link>

    <link name="link_6_joint">
      <inertial>
        <origin xyz="0 0 0.7493" rpy="0 0 0"/>
        <mass value="1.0"/>
        <inertia ixx="2186.28345" ixy="0" ixz="-0.05632" iyy="2121.90353" iyz="-0.00015" izz="0.48617"/>
      </inertial>
      <visual name="link_6">
        <origin xyz="0 0 0.74929" rpy="0 0 0"/>
        <geometry>
          <mesh filename="package://model_spawner/model/arm4/meshes/dae/link_6_mesh.dae" scale="4.0 4.0 1.0"/>
        </geometry>
        <material name="link_6_material"/>
      </visual>
      <collision name="link_6">
        <origin xyz="0 0 4.33324" rpy="3.14159 0 0"/>
        <geometry>
          <cylinder radius="4.58395" length="9.11999"/>
        </geometry>
      </collision>
    </link>

    <joint name="link_1_joint" type="continuous">
      <origin xyz="0.02008 0.61999 10.66318" rpy="0 0 0"/>
      <parent link="base_joint"/>
      <child link="link_1_joint"/>
      <axis xyz="0 0 1.0"/>
      <limit effort="1.0" velocity="1.0"/>
    </joint>

    <joint name="link_2_joint" type="revolute">
      <origin xyz="-0.02008 -6.26349 5.2697" rpy="1.5708 0 0"/>
      <parent link="link_1_joint"/>
      <child link="link_2_joint"/>
      <axis xyz="0 0 1.0"/>
      <limit lower="-1.57" upper="1.57" effort="1.0" velocity="1.0"/>
    </joint>

    <joint name="link_3_joint" type="revolute">
      <origin xyz="0 24.7971 -11.16805" rpy="0 -3.14159 0"/>
      <parent link="link_2_joint"/>
      <child link="link_3_joint"/>
      <axis xyz="0 0 1.0"/>
      <limit lower="-2.57" upper="2.57" effort="1.0" velocity="1.0"/>
    </joint>

    <joint name="link_4_joint" type="continuous">
      <origin xyz="0 21.37913 0.02204" rpy="1.5708 0 -3.14159"/>
      <parent link="link_3_joint"/>
      <child link="link_4_joint"/>
      <axis xyz="0 0 1.0"/>
      <limit effort="1.0" velocity="1.0"/>
    </joint>

    <joint name="link_5_joint" type="revolute">
      <origin xyz="0 0.00078 3.72826" rpy="1.5708 0 0"/>
      <parent link="link_4_joint"/>
      <child link="link_5_joint"/>
      <axis xyz="0 0 1.0"/>
      <limit lower="-1.57" upper="1.57" effort="1.0" velocity="1.0"/>
    </joint>

    <joint name="link_6_joint" type="continuous">
      <origin xyz="0 10.39911 0" rpy="-1.5708 0 0"/>
      <parent link="link_5_joint"/>
      <child link="link_6_joint"/>
      <axis xyz="0 0 1.0"/>
      <limit effort="1.0" velocity="1.0"/>
    </joint>

    <material name="base_material">
      <color rgba="0.00293 0.17898 0.64 1.0"/>
    </material>

    <material name="link_1_material">
      <color rgba="0.27804 0.56837 0.64 1.0"/>
    </material>

    <material name="link_2_material">
      <color rgba="0.03587 0.64 0.15975 1.0"/>
    </material>

    <material name="link_3_material">
      <color rgba="0.64 0.12974 0.1869 1.0"/>
    </material>

    <material name="link_4_material">
      <color rgba="0.63358 0.64 0.05655 1.0"/>
    </material>

    <material name="link_5_material">
      <color rgba="0.64 0.13903 0.59154 1.0"/>
    </material>

    <material name="link_6_material">
      <color rgba="0.27033 0.06955 0.64 1.0"/>
    </material>

  </robot>
