<?xml version="1.0"?>
<!-- created with Phobos 1.0.1 "Capricious Choutengan" -->
  <robot name="arm_v2">
	
	<link name="world"/>
	
    <link name="root">
      <inertial>
        <origin xyz="0.0 0.0 0.0" rpy="0 0 0"/>
        <mass value="1"/>
        <inertia ixx="0.120647201475" ixy="0.0" ixz="0.0" iyy="0.18821095363333332" iyz="0.000" izz="0.2852252495083333"/>
      </inertial>
      <visual name="base">
        <origin xyz="0 0 0" rpy="0 0 0"/>
        <geometry>
          <mesh filename="package://model_spawner/model/arm_old/meshes/dae/base_mesh.dae" scale="0.57139 0.57139 0.57854"/>
        </geometry>
        <material name="black"/>
      </visual>
      <collision name="base_collision">
        <origin xyz="0 0 -0.00046" rpy="0 0 0"/>
        <geometry>
          <box size="1.4549 1.14279 0.37656"/>
        </geometry>
      </collision>
    </link>
    
    <joint name="world_root" type="fixed">
      <parent link="world"/>
      <child link="root"/>
    </joint>    
    
    <link name="joint_1">
      <inertial>
        <origin xyz="0.0 0 0" rpy="0 0 0"/>
        <mass value="1"/>
	<inertia ixx="0.06938235784166667" ixy="0.0" ixz="0.0" iyy="0.06938235784166667" iyz="0.0" izz="0.13139440166666666"/>
      </inertial>
      <visual name="link_1">
        <origin xyz="0 0 0" rpy="0 0 0"/>
        <geometry>
          <mesh filename="package://model_spawner/model/arm_old/meshes/dae/link_1_mesh.dae" scale="0.44395 0.44395 0.44395"/>
        </geometry>
        <material name="blue"/>
      </visual>
      <collision name="link_1_collision">
        <origin xyz="0 0 -0.00244" rpy="0 0 0"/>
        <geometry>
          <box size="0.8879 0.8879 0.21029"/>
        </geometry>
      </collision>
    </link>
    
    <joint name="root__joint_1" type="continuous">
      <origin xyz="-0.05831 0 0.28533" rpy="0 0 0"/>
      <parent link="root"/>
      <child link="joint_1"/>
      <axis xyz="0 0 1.0"/>
      <limit effort="80.0" velocity="1.0"/>
    </joint>
    
    <link name="joint_2">
      <inertial>
        <origin xyz="-0.61365 0.0 0.0" rpy="0 -1.5708 0"/>
        <mass value="1"/>
        <inertia ixx="0.12974743654166665" ixy="0.0" ixz="-0.0" iyy="0.12974743654166665" iyz="0.0" izz="0.012614252016666667"/>
      </inertial>
      <visual name="link_2">
        <origin xyz="-0.61365 0 0" rpy="0 -1.5708 0"/>
        <geometry>
          <mesh filename="package://model_spawner/model/arm_old/meshes/dae/link_2_mesh.dae" scale="0.13679 0.13679 0.13679"/>
        </geometry>
        <material name="green"/>
      </visual>
      <collision name="link_2_collision">
        <origin xyz="-0.61365 0 0" rpy="0 -1.5708 0"/>
        <geometry>
          <box size="0.27511 0.27359 1.21708"/>
        </geometry>
      </collision>
    </link>
    
    <joint name="joint_1__joint_2" type="revolute">
      <origin xyz="-0.05473 0 0.23728" rpy="0 1.5708 0"/>
      <parent link="joint_1"/>
      <child link="joint_2"/>
      <axis xyz="0 0 1.0"/>
      <limit lower="-1.57" upper="1.57" effort="140.0" velocity="1.0"/>
    </joint>
    
    <link name="joint_3">
      <inertial>
        <origin xyz="-0.07827 0 0" rpy="0 -1.5708 0"/>
        <mass value="1"/>
        <inertia ixx="0.04964787921666666" ixy="0.0" ixz="0.0" iyy="0.04971738121666666" iyz="0.0" izz="0.012544750016666665"/>
      </inertial>
      <visual name="link_3">
        <origin xyz="-0.07827 0 0" rpy="0 -1.5708 0"/>
        <geometry>
          <mesh filename="package://model_spawner/model/arm_old/meshes/dae/link_3_mesh.dae" scale="0.13679 0.13679 0.13679"/>
        </geometry>
        <material name="red"/>
      </visual>
      <collision name="link_3_collision">
        <origin xyz="-0.07756 0 -0.00041" rpy="0 -1.5708 0"/>
        <geometry>
          <box size="0.27511 0.27359 0.72175"/>
        </geometry>
      </collision>
    </link>
    
    <joint name="joint_2__joint_3" type="revolute">
      <origin xyz="-1.21558 0 0.22654" rpy="-3.14159 0 0"/>
      <parent link="joint_2"/>
      <child link="joint_3"/>
      <axis xyz="0 0 1.0"/>
      <limit lower="-2.7" upper="2.7" effort="100.0" velocity="1.0"/>
    </joint>
    
    <link name="joint_4">
      <inertial>
        <origin xyz="0 0 0.25186" rpy="0 0 0"/>
        <mass value="1"/>
        <inertia ixx="0.015845462408333334" ixy="0.0" ixz="0.0" iyy="0.015845462408333334" iyz="0.0" izz="0.0070726666666666655"/>
      </inertial>
      <visual name="link_4">
        <origin xyz="0 0 0.25186" rpy="0 0 0"/>
        <geometry>
          <mesh filename="package://model_spawner/model/arm_old/meshes/dae/link_4_mesh.dae" scale="0.13679 0.13679 0.13679"/>
        </geometry>
        <material name="yellow"/>
      </visual>
      <collision name="link_4_collision">
        <origin xyz="-0.0014 -0.00039 0.25116" rpy="0 0 0"/>
        <geometry>
          <box size="0.206 0.206 0.38433"/>
        </geometry>
      </collision>
    </link> 
   
    <joint name="joint_3__joint_4" type="continuous">
      <origin xyz="-0.70904 0.00014 -0.02449" rpy="0 -1.5708 0"/>
      <parent link="joint_3"/>
      <child link="joint_4"/>
      <axis xyz="0 0 1.0"/>
      <limit effort="10.0" velocity="1.0"/>
    </joint>   
   
    <link name="joint_5">
      <inertial>
        <origin xyz="-0.11797 0 0" rpy="0 -1.5708 0"/>
        <mass value="1"/>
        <inertia ixx="0.0036144393750000003" ixy="0.0" ixz="0.0" iyy="0.003666514283333334" iyz="0.0" izz="0.0022157955083333333"/>
      </inertial>
      <visual name="link_5">
        <origin xyz="-0.11797 0 0" rpy="0 -1.5708 0"/>
        <geometry>
          <mesh filename="package://model_spawner/model/arm_old/meshes/dae/link_5_mesh.dae" scale="0.05697 0.05697 0.05697"/>
        </geometry>
        <material name="green"/>
      </visual>
      <collision name="link_5_collision">
        <origin xyz="-0.11739 0 -0.00068" rpy="0 -1.5708 0"/>
        <geometry>
          <box size="0.11665 0.11394 0.17433"/>
        </geometry>
      </collision>
    </link>   

    <joint name="joint_4__joint_5" type="revolute">
      <origin xyz="0.00035 -0.00014 0.33166" rpy="-3.14159 1.5708 0"/>
      <parent link="joint_4"/>
      <child link="joint_5"/>
      <axis xyz="0 0 1.0"/>
      <limit lower="-1.57" upper="1.57" effort="10.0" velocity="1.0"/>
    </joint>

    <link name="joint_6">
      <inertial>
        <origin xyz="0.01466 0 0.0667" rpy="0 0 0"/>
        <mass value="1"/>
        <inertia ixx="0.004469016741666667" ixy="0.0" ixz="0.0" iyy="0.005419473066666666" iyz="0.0" izz="0.003039256741666666"/>
      </inertial>
      <visual name="link_6">
        <origin xyz="0.01466 0 0.0667" rpy="0 0 0"/>
        <geometry>
          <mesh filename="package://model_spawner/model/arm_old/meshes/dae/link_6_mesh.dae" scale="0.0573 0.05598 0.04254"/>
        </geometry>
        <material name="red"/>
      </visual>
      <collision name="link_6_collision">
        <origin xyz="0.01397 0 0.06703" rpy="0 0 0"/>
        <geometry>
          <box size="0.15472 0.11195 0.20272"/>
        </geometry>
      </collision>
    </link>

    <joint name="joint_5__joint_6" type="continuous">
      <origin xyz="-0.26991 0 0" rpy="0 -1.5708 0"/>
      <parent link="joint_5"/>
      <child link="joint_6"/>
      <axis xyz="0 0 1.0"/>
      <limit effort="10.0" velocity="1.0"/>
    </joint>

    <material name="black">
      <color rgba="0.09542 0.09542 0.09542 1.0"/>
    </material>

    <material name="blue">
      <color rgba="0.04499 0.26049 0.64 1.0"/>
    </material>

    <material name="green">
      <color rgba="0.02311 0.64 0.28759 1.0"/>
    </material>

    <material name="red">
      <color rgba="0.64 0.09786 0.17201 1.0"/>
    </material>

    <material name="yellow">
      <color rgba="0.62332 0.64 0.13787 1.0"/>
    </material>

	<gazebo>
	  <plugin name="gazebo_ros_control" filename="libgazebo_ros_control.so">
	    <robotNamespace>/arm_cotroll</robotNamespace>
	  </plugin>
	  
      <plugin name="joint_state_publisher" filename="libgazebo_ros_joint_state_publisher.so">
        <jointName>root__joint_1,joint_1__joint_2,joint_2__joint_3,joint_3__joint_4,joint_4__joint_5,joint_5__joint_6</jointName>
	  </plugin>
	</gazebo>

	<transmission name="tran_1">
      <type>transmission_interface/SimpleTransmission</type>
	  <joint name="root__joint_1">
	    <hardwareInterface>hardware_interface/EffortJointInterface</hardwareInterface>
	  </joint>
      <actuator name="motor_1">
        <hardwareInterface>hardware_interface/EffortJointInterface</hardwareInterface>
        <mechanicalReduction>1</mechanicalReduction>
      </actuator>
    </transmission>
    
    <transmission name="tran_2">
      <type>transmission_interface/SimpleTransmission</type>
	  <joint name="joint_1__joint_2">
	    <hardwareInterface>hardware_interface/EffortJointInterface</hardwareInterface>
	  </joint>
      <actuator name="motor_2">
        <hardwareInterface>hardware_interface/EffortJointInterface</hardwareInterface>
        <mechanicalReduction>1</mechanicalReduction>
      </actuator>
    </transmission>

    <transmission name="tran_3">
      <type>transmission_interface/SimpleTransmission</type>
	  <joint name="joint_2__joint_3">
	    <hardwareInterface>hardware_interface/EffortJointInterface</hardwareInterface>
	  </joint>
      <actuator name="motor_3">
        <hardwareInterface>hardware_interfaceEffortJointInterface</hardwareInterface>
        <mechanicalReduction>1</mechanicalReduction>
      </actuator>
    </transmission>

    <transmission name="tran_4">
      <type>transmission_interface/SimpleTransmission</type>
	  <joint name="joint_3__joint_4">
	    <hardwareInterface>hardware_interface/EffortJointInterface</hardwareInterface>
	  </joint>
      <actuator name="motor_4">
        <hardwareInterface>hardware_interface/EffortJointInterface</hardwareInterface>
        <mechanicalReduction>1</mechanicalReduction>
      </actuator>
    </transmission>

    <transmission name="tran_5">
      <type>transmission_interface/SimpleTransmission</type>
	  <joint name="joint_4__joint_5">
	    <hardwareInterface>hardware_interface/EffortJointInterface</hardwareInterface>
	  </joint>
      <actuator name="motor_5">
        <hardwareInterface>EffortJointInterface</hardwareInterface>
        <mechanicalReduction>1</mechanicalReduction>
      </actuator>
    </transmission>

    <transmission name="tran_6">
      <type>transmission_interface/SimpleTransmission</type>
 	  <joint name="joint_5__joint_6">
	    <hardwareInterface>hardware_interface/EffortJointInterface</hardwareInterface>
	  </joint>
      <actuator name="motor_6">
        <hardwareInterface>hardware_interface/EffortJointInterface</hardwareInterface>
        <mechanicalReduction>1</mechanicalReduction>
      </actuator>
    </transmission>

  </robot>
