<?xml version="1.0"?>
<!-- created with Phobos 1.0.1 "Capricious Choutengan" -->
  <robot name="arm_v2_inertial">

    <link name="joint_1">
      <inertial>
        <origin xyz="0.00020157 -0.000000 -0.00010604" rpy="0 0 0"/>
        <mass value="1"/>
	<inertia ixx="0.00395609" ixy="0.000" ixz="0.00015044" iyy="0.000402509" iyz="0.000" izz="0.00685462"/>
      </inertial>
      <visual name="link_1">
        <origin xyz="0 0 0" rpy="0 0 0"/>
        <geometry>
          <mesh filename="package://arm_controll/model/meshes/dae/link_1_mesh.dae" scale="0.44395 0.44395 0.44395"/>
        </geometry>
        <material name="blue"/>
      </visual>
      <collision name="link_1_collision">
        <origin xyz="0 0 -0.00244" rpy="0 0 0"/>
        <geometry>
          <box size="0.8879 0.8879 0.21029"/>
        </geometry>
      </collision>
    </link>

    <link name="joint_2">
      <inertial>
        <origin xyz="-0.00150945 0.00000019 0.00000005" rpy="0 0 0"/>
        <mass value="1"/>
        <inertia ixx="2.57993744" ixy="-0.00000013" ixz="-0.00000001" iyy="2.58461945" iyz="0.000" izz="0.09876421"/>
      </inertial>
      <visual name="link_2">
        <origin xyz="-0.61365 0 0" rpy="0 -1.5708 0"/>
        <geometry>
          <mesh filename="package://arm_controll/model/meshes/dae/link_2_mesh.dae" scale="0.13679 0.13679 0.13679"/>
        </geometry>
        <material name="green"/>
      </visual>
      <collision name="link_2_collision">
        <origin xyz="-0.61365 0 0" rpy="0 -1.5708 0"/>
        <geometry>
          <box size="0.27511 0.27359 1.21708"/>
        </geometry>
      </collision>
    </link>

    <link name="joint_3">
      <inertial>
        <origin xyz="-0.00145363 0.00000934 0.01026809" rpy="0 0 0"/>
        <mass value="1"/>
        <inertia ixx="0.28288637" ixy="-0.00000007" ixz="0.00880319" iyy="0.28522650" iyz="-0.00000001" izz="0.04925734"/>
      </inertial>
      <visual name="link_3">
        <origin xyz="-0.07827 0 0" rpy="0 -1.5708 0"/>
        <geometry>
          <mesh filename="package://arm_controll/model/meshes/dae/link_3_mesh.dae" scale="0.13679 0.13679 0.13679"/>
        </geometry>
        <material name="red"/>
      </visual>
      <collision name="link_3_collision">
        <origin xyz="-0.07756 0 -0.00041" rpy="0 -1.5708 0"/>
        <geometry>
          <box size="0.27511 0.27359 0.72175"/>
        </geometry>
      </collision>
    </link>

    <link name="joint_4">
      <inertial>
        <origin xyz="-0.00011525 -0.00002971 -0.10680014" rpy="0 0 0"/>
        <mass value="1"/>
        <inertia ixx="0.0462848" ixy="0.00000609" ixz="0.00012441" iyy="0.04801012" iyz="0.00001492" izz="0.1408534"/>
      </inertial>
      <visual name="link_4">
        <origin xyz="0 0 0.25186" rpy="0 0 0"/>
        <geometry>
          <mesh filename="package://arm_controll/model/meshes/dae/link_4_mesh.dae" scale="0.13679 0.13679 0.13679"/>
        </geometry>
        <material name="yellow"/>
      </visual>
      <collision name="link_4_collision">
        <origin xyz="-0.0014 -0.00039 0.25116" rpy="0 0 0"/>
        <geometry>
          <box size="0.206 0.206 0.38433"/>
        </geometry>
      </collision>
    </link>

    <link name="joint_5">
      <inertial>
        <origin xyz="-0.00002625 0.00000002 -0.00560230" rpy="0 0 0"/>
        <mass value="1"/>
        <inertia ixx="0.31435614" ixy="0.00000164" ixz="-0.00161520" iyy="0.31900312" iyz="0.00000452" izz="0.8525150"/>
      </inertial>
      <visual name="link_5">
        <origin xyz="-0.11797 0 0" rpy="0 -1.5708 0"/>
        <geometry>
          <mesh filename="package://arm_controll/model/meshes/dae/link_5_mesh.dae" scale="0.05697 0.05697 0.05697"/>
        </geometry>
        <material name="green"/>
      </visual>
      <collision name="link_5_collision">
        <origin xyz="-0.11739 0 -0.00068" rpy="0 -1.5708 0"/>
        <geometry>
          <box size="0.11665 0.11394 0.17433"/>
        </geometry>
      </collision>
    </link>

    <link name="joint_6">
      <inertial>
        <origin xyz="-0.00014927 -0.00000000 -0.00450842" rpy="0 0 0"/>
        <mass value="1"/>
        <inertia ixx="0.11457040" ixy="0.000" ixz="-0.02028147" iyy="0.12297392" iyz="0.000" izz="0.01515981"/>
      </inertial>
      <visual name="link_6">
        <origin xyz="0.01466 0 0.0667" rpy="0 0 0"/>
        <geometry>
          <mesh filename="package://arm_controll/model/meshes/dae/link_6_mesh.dae" scale="0.0573 0.05598 0.04254"/>
        </geometry>
        <material name="red"/>
      </visual>
      <collision name="link_6_collision">
        <origin xyz="0.01397 0 0.06703" rpy="0 0 0"/>
        <geometry>
          <box size="0.15472 0.11195 0.20272"/>
        </geometry>
      </collision>
    </link>

    <link name="root">
      <inertial>
        <origin xyz="0.00077911 -0.000000 -0.00061613" rpy="0 0 0"/>
        <mass value="1"/>
        <inertia ixx="0.00618451" ixy="0.000" ixz="0.00000887" iyy="0.01013616" iyz="0.000" izz="0.01470437"/>
      </inertial>
      <visual name="base">
        <origin xyz="0 0 0" rpy="0 0 0"/>
        <geometry>
          <mesh filename="package://arm_controll/model/meshes/dae/base_mesh.dae" scale="0.57139 0.57139 0.57854"/>
        </geometry>
        <material name="black"/>
      </visual>
      <collision name="base_collision">
        <origin xyz="0 0 -0.00046" rpy="0 0 0"/>
        <geometry>
          <box size="1.4549 1.14279 0.37656"/>
        </geometry>
      </collision>
    </link>

    <joint name="joint_1" type="continuous">
      <origin xyz="-0.05831 0 0.28533" rpy="0 0 0"/>
      <parent link="root"/>
      <child link="joint_1"/>
      <axis xyz="0 0 1.0"/>
      <limit effort="1.0" velocity="1.0"/>
    </joint>

    <joint name="joint_2" type="revolute">
      <origin xyz="-0.05473 0 0.23728" rpy="0 1.5708 0"/>
      <parent link="joint_1"/>
      <child link="joint_2"/>
      <axis xyz="0 0 1.0"/>
      <limit lower="-1.57" upper="1.57" effort="1.0" velocity="1.0"/>
    </joint>

    <joint name="joint_3" type="revolute">
      <origin xyz="-1.21558 0 0.22654" rpy="-3.14159 0 0"/>
      <parent link="joint_2"/>
      <child link="joint_3"/>
      <axis xyz="0 0 1.0"/>
      <limit lower="-2.7" upper="2.7" effort="1.0" velocity="1.0"/>
    </joint>

    <joint name="joint_4" type="continuous">
      <origin xyz="-0.70904 0.00014 -0.02449" rpy="0 -1.5708 0"/>
      <parent link="joint_3"/>
      <child link="joint_4"/>
      <axis xyz="0 0 1.0"/>
      <limit effort="1.0" velocity="1.0"/>
    </joint>

    <joint name="joint_5" type="revolute">
      <origin xyz="0.00035 -0.00014 0.33166" rpy="-3.14159 1.5708 0"/>
      <parent link="joint_4"/>
      <child link="joint_5"/>
      <axis xyz="0 0 1.0"/>
      <limit lower="-1.57" upper="1.57" effort="1.0" velocity="1.0"/>
    </joint>

    <joint name="joint_6" type="continuous">
      <origin xyz="-0.26991 0 0" rpy="0 -1.5708 0"/>
      <parent link="joint_5"/>
      <child link="joint_6"/>
      <axis xyz="0 0 1.0"/>
      <limit effort="1.0" velocity="1.0"/>
    </joint>

    <material name="black">
      <color rgba="0.09542 0.09542 0.09542 1.0"/>
    </material>

    <material name="blue">
      <color rgba="0.04499 0.26049 0.64 1.0"/>
    </material>

    <material name="green">
      <color rgba="0.02311 0.64 0.28759 1.0"/>
    </material>

    <material name="red">
      <color rgba="0.64 0.09786 0.17201 1.0"/>
    </material>

    <material name="yellow">
      <color rgba="0.62332 0.64 0.13787 1.0"/>
    </material>

  </robot>
