<?xml version="1.0" ?>
<robot name="vehicle">

  <joint name="vehicle__center_axel__front_axel" type="revolute">
    <parent link="vehicle__center_axel"/>
    <child link="vehicle__front_axel"/>
    <origin xyz="0.78 0   0" rpy="0     0     1.5708"/>
    <axis xyz="0 0 1"/>
    <limit lower="-0.4795" upper="0.4795" effort="5.0" velocity="1.0"/>
  </joint>
  
  <joint name="vehicle__front_axel__front_left_wheel" type="continuous">
    <parent link="vehicle__front_axel"/>
    <child link="vehicle__front_left_wheel"/>
    <origin xyz="0.56699 0      0" rpy="1.5708  0     -1.5708"/>
    <axis xyz="0 0 1"/>
    <limit effort="1.0" velocity="1.0"/>
  </joint>
  
  <joint name="vehicle__front_axel__front_right_wheel" type="continuous">
    <parent link="vehicle__front_axel"/>
    <child link="vehicle__front_right_wheel"/>
    <origin xyz="-0.56699  0       0" rpy="1.5708  0     -1.5708"/>
    <axis xyz="0 0 1"/>
    <limit effort="1.0" velocity="1.0"/>
  </joint>
  
  <joint name="vehicle__rear_axel__rear_left_wheel" type="fixed">
    <parent link="vehicle__rear_axel"/>
    <child link="vehicle__rear_left_wheel"/>
    <origin xyz="0       0      -0.56699" rpy="0 0 0"/>
    <axis xyz="0 0 0"/>
    <limit lower="0" upper="0" effort="0" velocity="0"/>
  </joint>
  
  <joint name="vehicle__rear_axel__rear_right_wheel" type="fixed">
    <parent link="vehicle__rear_axel"/>
    <child link="vehicle__rear_right_wheel"/>
    <origin xyz="0      0      0.56699" rpy="0 0 0"/>
    <axis xyz="0 0 0"/>
    <limit lower="0" upper="0" effort="0" velocity="0"/>
  </joint>
  
  <joint name="vehicle__center_axel__rear_axel" type="continuous">
    <parent link="vehicle__center_axel"/>
    <child link="vehicle__rear_axel"/>
    <origin xyz="-0.78  0    0" rpy="1.5708 0     0"/>
    <axis xyz="0 0 -1"/>
    <limit effort="10.0" velocity="1.0"/>
  </joint>
  
  <link name="vehicle__front_right_wheel">
    <inertial>
      <mass value="2.70774"/>
      <origin xyz="0 0 0" rpy="0 0 0"/>
      <inertia ixx="0.0522819" ixy="0" ixz="0" iyy="0.0522819" iyz="0" izz="0.0915216"/>
    </inertial>
    <collision name="vehicle__collision">
      <origin xyz="0 0 0" rpy="0 0 0"/>
      <geometry>
        <cylinder radius="0.26" length="0.17"/>
      </geometry>
    </collision>
    <visual name="vehicle__visual">
      <origin xyz="0 0 0" rpy="0 0 0"/>
      <geometry>
        <cylinder radius="0.26" length="0.17"/>
      </geometry>
    </visual>
  </link>
  
  <link name="vehicle__rear_axel">
    <inertial>
      <mass value="0.923608"/>
      <origin xyz="0 0 0" rpy="0 0 0"/>
      <inertia ixx="0.0662345" ixy="0" ixz="0" iyy="0.0662345" iyz="0" izz="0.00115451"/>
    </inertial>
    <collision name="vehicle__collision">
      <origin xyz="0 0 0" rpy="0 0 0"/>
      <geometry>
        <cylinder radius="0.05" length="0.923609"/>
      </geometry>
    </collision>
    <visual name="vehicle__visual">
      <origin xyz="0 0 0" rpy="0 0 0"/>
      <geometry>
        <cylinder radius="0.05" length="0.923609"/>
      </geometry>
    </visual>
  </link>
  
  <link name="vehicle__front_left_wheel">
    <inertial>
      <mass value="2.70774"/>
      <origin xyz="0 0 0" rpy="0 0 0"/>
      <inertia ixx="0.0522819" ixy="0" ixz="0" iyy="0.0522819" iyz="0" izz="0.0915216"/>
    </inertial>
    <collision name="vehicle__collision">
      <origin xyz="0 0 0" rpy="0 0 0"/>
      <geometry>
        <cylinder radius="0.26" length="0.17"/>
      </geometry>
    </collision>
    <visual name="vehicle__visual">
      <origin xyz="0 0 0" rpy="0 0 0"/>
      <geometry>
        <cylinder radius="0.26" length="0.17"/>
      </geometry>
    </visual>
  </link>
  
  <link name="vehicle__rear_right_wheel">
    <inertial>
      <mass value="4.99293"/>
      <origin xyz="0 0 0" rpy="0 0 0"/>
      <inertia ixx="0.152004" ixy="0" ixz="0" iyy="0.152004" iyz="0" izz="0.27269"/>
    </inertial>
    <collision name="vehicle__collision">
      <origin xyz="0 0 0" rpy="0 0 0"/>
      <geometry>
        <cylinder radius="0.3305" length="0.194"/>
      </geometry>
    </collision>
    <visual name="vehicle__visual">
      <origin xyz="0 0 0" rpy="0 0 0"/>
      <geometry>
        <cylinder radius="0.3305" length="0.194"/>
      </geometry>
    </visual>
  </link>
  
  <link name="vehicle__rear_left_wheel">
    <inertial>
      <mass value="4.99293"/>
      <origin xyz="0 0 0" rpy="0 0 0"/>
      <inertia ixx="0.152004" ixy="0" ixz="0" iyy="0.152004" iyz="0" izz="0.27269"/>
    </inertial>
    <collision name="vehicle__collision">
      <origin xyz="0 0 0" rpy="0 0 0"/>
      <geometry>
        <cylinder radius="0.3305" length="0.194"/>
      </geometry>
    </collision>
    <visual name="vehicle__visual">
      <origin xyz="0 0 0" rpy="0 0 0"/>
      <geometry>
        <cylinder radius="0.3305" length="0.194"/>
      </geometry>
    </visual>
  </link>
  
  <link name="vehicle__center_axel">
    <inertial>
      <mass value="0.495529"/>
      <origin xyz="0 0 0" rpy="0 0 0"/>
      <inertia ixx="0.00040468" ixy="0" ixz="0" iyy="0.0752801" iyz="0" izz="0.0752801"/>
    </inertial>
    <collision name="vehicle__collision">
      <origin xyz="0 0 0" rpy="0 0 0"/>
      <geometry>
        <box size="1.34838 0.07 0.07"/>
      </geometry>
    </collision>
    <visual name="vehicle__visual">
      <origin xyz="0 0 0" rpy="0 0 0"/>
      <geometry>
        <box size="1.34838 0.07 0.07"/>
      </geometry>
    </visual>
  </link>
  
  <link name="vehicle__front_axel">
    <inertial>
      <mass value="0.348248"/>
      <origin xyz="0 0 0" rpy="0 0 0"/>
      <inertia ixx="0.0002844" ixy="0" ixz="0" iyy="0.026202" iyz="0" izz="0.026202"/>
    </inertial>
    <collision name="vehicle__collision">
      <origin xyz="0 0 0" rpy="0 0 0"/>
      <geometry>
        <box size="0.947614 0.07 0.07"/>
      </geometry>
    </collision>
    <visual name="vehicle__visual">
      <origin xyz="0 0 0" rpy="0 0 0"/>
      <geometry>
        <box size="0.947614 0.07 0.07"/>
      </geometry>
    </visual>
  </link>
  
  <transmission name="tran_front_steering">
    <type>transmission_interface/SimpleTransmission</type>
	  <joint name="vehicle__center_axel__front_axel">
  	  <hardwareInterface>hardware_interface/PositionJointInterface</hardwareInterface>
  	</joint>
    <actuator name="motor__vehicle__center_axel__front_axel">
      <hardwareInterface>hardware_interface/PositionJointInterface</hardwareInterface>
      <mechanicalReduction>1</mechanicalReduction>
    </actuator>
  </transmission>   

  <transmission name="tran_rear_drive">
    <type>transmission_interface/SimpleTransmission</type>
	  <joint name="vehicle__center_axel__rear_axel">
	    <hardwareInterface>hardware_interface/VelocityJointInterface</hardwareInterface>
	  </joint>
    <actuator name="motor__vehicle__center_axel__rear_axel">
      <hardwareInterface>hardware_interface/VelocityJointInterface</hardwareInterface>
      <mechanicalReduction>1</mechanicalReduction>
    </actuator>
  </transmission>  

  <gazebo>
    <self_collide>1</self_collide>
    
    <plugin name="gazebo_ros_control" filename="libgazebo_ros_control.so">
      <robotNamespace></robotNamespace>
      <robotSimType>gazebo_ros_control/DefaultRobotHWSim</robotSimType>
      <legacyModeNS>false</legacyModeNS>
    </plugin>
    
	<plugin name="joint_state_publisher" filename="libgazebo_ros_joint_state_publisher.so">
    <jointName>
  		vehicle__center_axel__rear_axel,
  		vehicle__center_axel__front_axel,
  		vehicle__front_axel__front_right_wheel,
  		vehicle__front_axel__front_left_wheel
    </jointName>
  </plugin>
  </gazebo>
</robot>
