<?xml version="1.0"?>
<!-- created with Phobos 1.0.1 "Capricious Choutengan" -->
  <robot name="arm_scale">

    <link name="world"/>

    <link name="base">
      <inertial>
        <origin xyz="0 0 -0.17444" rpy="0 0 0"/>
        <mass value="1.0"/>
        <inertia ixx="0.45813" ixy="0" ixz="0" iyy="0.45813" iyz="0" izz="0.78125"/>
      </inertial>
      <visual name="base_visual">
        <origin xyz="0 0 0" rpy="0 0 0"/>
        <geometry>
          <mesh filename="package://model_spawner/model/arm_small/meshes/dae/base_mesh.dae" scale="1.25 1.25 0.45"/>
        </geometry>
        <material name="base_material"/>
      </visual>
      <collision name="base">
        <origin xyz="0 0 -0.17444" rpy="0 0 0"/>
        <geometry>
          <cylinder radius="1.25" length="0.9"/>
        </geometry>
      </collision>
    </link>

    <link name="griper_arm_left">
      <inertial>
        <origin xyz="-0.63465 0.20252 0" rpy="0 -1.5708 0"/>
        <mass value="1.0"/>
        <inertia ixx="0.07417" ixy="0" ixz="0" iyy="0.0197" iyz="0" izz="0.01781"/>
      </inertial>
      <visual name="griper_arm_left_visual">
        <origin xyz="-0.55479 0.17602 0" rpy="0 -1.5708 0"/>
        <geometry>
          <mesh filename="package://model_spawner/model/arm_small/meshes/dae/griper_arm_left_mesh.dae" scale="0.56044 0.56044 0.14011"/>
        </geometry>
        <material name="griper_material"/>
      </visual>
      <collision name="griper_arm_left">
        <origin xyz="-0.63465 0.20252 0" rpy="0 -1.5708 0"/>
        <geometry>
          <box size="0.45483 0.26693 1.04278"/>
        </geometry>
      </collision>
    </link>

    <link name="griper_arm_right">
      <inertial>
        <origin xyz="0.63471 0.20229 4e-05" rpy="0 1.5708 0"/>
        <mass value="1.0"/>
        <inertia ixx="0.07417" ixy="0" ixz="0" iyy="0.0197" iyz="0" izz="0.01781"/>
      </inertial>
      <visual name="griper_arm_right_visual">
        <origin xyz="0.55479 0.1758 4e-05" rpy="0 1.5708 0"/>
        <geometry>
          <mesh filename="package://model_spawner/model/arm_small/meshes/dae/griper_arm_right_mesh.dae" scale="0.56044 0.56044 0.14011"/>
        </geometry>
        <material name="griper_material"/>
      </visual>
      <collision name="griper_arm_right">
        <origin xyz="0.63471 0.20229 4e-05" rpy="0 1.5708 0"/>
        <geometry>
          <box size="0.45483 0.26693 1.04268"/>
        </geometry>
      </collision>
    </link>

    <link name="griper_base">
      <inertial>
        <origin xyz="0 0 0" rpy="-3.14159 0 0"/>
        <mass value="1.0"/>
        <inertia ixx="0.0112" ixy="0" ixz="0" iyy="0.0112" iyz="0" izz="0.0003"/>
      </inertial>
      <visual name="griper_base.001">
        <origin xyz="0 0 0" rpy="0 0 0"/>
        <geometry>
          <mesh filename="package://model_spawner/model/arm_small/meshes/dae/griper_base_mesh.dae" scale="0.20814 0.09655 0.05204"/>
        </geometry>
        <material name="griper_material"/>
      </visual>
      <collision name="griper_base">
        <origin xyz="0 0 0" rpy="-3.14159 0 0"/>
        <geometry>
          <cylinder radius="0.20814" length="0.0661"/>
        </geometry>
      </collision>
    </link>

    <link name="link_1">
      <inertial>
        <origin xyz="-0.00201 -0.062 -0.43101" rpy="0 0 0"/>
        <mass value="1.0"/>
        <inertia ixx="0.29101" ixy="0" ixz="0" iyy="0.29101" iyz="0" izz="0.5"/>
      </inertial>
      <visual name="link_1_visual">
        <origin xyz="0 0 0" rpy="0 0 0"/>
        <geometry>
          <mesh filename="package://model_spawner/model/arm_small/meshes/dae/link_1_mesh.dae" scale="1.0 1.0 0.35"/>
        </geometry>
        <material name="link_1_material"/>
      </visual>
      <collision name="link_1">
        <origin xyz="-0.00201 -0.062 -0.43101" rpy="0 0 0"/>
        <geometry>
          <cylinder radius="1.0" length="0.70155"/>
        </geometry>
      </collision>
    </link>

    <link name="link_2">
      <inertial>
        <origin xyz="0 1.45059 -0.05625" rpy="0 0 0"/>
        <mass value="1.0"/>
        <inertia ixx="0.81177" ixy="0" ixz="0" iyy="0.81177" iyz="0" izz="0.12474"/>
      </inertial>
      <visual name="link_2_visual">
        <origin xyz="0 1.25 0" rpy="0 0 0"/>
        <geometry>
          <mesh filename="package://model_spawner/model/arm_small/meshes/dae/link_2_mesh.dae" scale="0.4 0.4 0.4"/>
        </geometry>
        <material name="link_2_material"/>
      </visual>
      <collision name="link_2">
        <origin xyz="0 1.45059 -0.05625" rpy="1.5708 0 0"/>
        <geometry>
          <cylinder radius="0.49947" length="2.9988"/>
        </geometry>
      </collision>
    </link>

    <link name="link_3">
      <inertial>
        <origin xyz="0 0.41667 -0.05636" rpy="1.5708 0 0"/>
        <mass value="1.0"/>
        <inertia ixx="0.30115" ixy="0" ixz="0" iyy="0.30115" iyz="0" izz="0.12474"/>
      </inertial>
      <visual name="link_3_visual">
        <origin xyz="0 0 0" rpy="0 0 0"/>
        <geometry>
          <mesh filename="package://model_spawner/model/arm_small/meshes/dae/link_3_mesh.dae" scale="0.4 0.4 0.4"/>
        </geometry>
        <material name="link_3_material"/>
      </visual>
      <collision name="link_3">
        <origin xyz="0 0.41667 -0.05636" rpy="1.5708 0 0"/>
        <geometry>
          <cylinder radius="0.49947" length="1.69276"/>
        </geometry>
      </collision>
    </link>

    <link name="link_4">
      <inertial>
        <origin xyz="0 0 -0.44558" rpy="0 0 0"/>
        <mass value="1.0"/>
        <inertia ixx="0.09797" ixy="0" ixz="0" iyy="0.09797" iyz="0" izz="0.08"/>
      </inertial>
      <visual name="link_4_visual">
        <origin xyz="0 0 -0.04043" rpy="0 0 0"/>
        <geometry>
          <mesh filename="package://model_spawner/model/arm_small/meshes/dae/link_4_mesh.dae" scale="0.4 0.4 0.625"/>
        </geometry>
        <material name="link_4_material"/>
      </visual>
      <collision name="link_4">
        <origin xyz="0 0 -0.44558" rpy="0 0 0"/>
        <geometry>
          <cylinder radius="0.4" length="0.83404"/>
        </geometry>
      </collision>
    </link>

    <link name="link_5">
      <inertial>
        <origin xyz="0 0.71867 8e-05" rpy="-1.5708 0 0"/>
        <mass value="1.0"/>
        <inertia ixx="0.06825" ixy="0" ixz="0" iyy="0.06825" iyz="0" izz="0.08"/>
      </inertial>
      <visual name="link_5_visual">
        <origin xyz="0 0.36415 0" rpy="-1.5708 0 0"/>
        <geometry>
          <mesh filename="package://model_spawner/model/arm_small/meshes/dae/link_5_mesh.dae" scale="0.4 0.4 0.4"/>
        </geometry>
        <material name="link_5_material"/>
      </visual>
      <collision name="link_5">
        <origin xyz="0 0.71867 8e-05" rpy="-1.5708 0 0"/>
        <geometry>
          <cylinder radius="0.4" length="0.58223"/>
        </geometry>
      </collision>
    </link>

    <link name="link_6">
      <inertial>
        <origin xyz="0 0 0.00902" rpy="0 0 0"/>
        <mass value="1.0"/>
        <inertia ixx="0.08072" ixy="0" ixz="0" iyy="0.08072" iyz="0" izz="2e-05"/>
      </inertial>
      <visual name="link_6_visual">
        <origin xyz="0 0 0.07493" rpy="0 0 0"/>
        <geometry>
          <mesh filename="package://model_spawner/model/arm_small/meshes/dae/link_6_mesh.dae" scale="0.4 0.4 0.1"/>
        </geometry>
        <material name="link_6_material"/>
      </visual>
      <collision name="link_6">
        <origin xyz="0 0 0.00902" rpy="0 0 0"/>
        <geometry>
          <cylinder radius="0.4" length="0.06561"/>
        </geometry>
      </collision>
    </link>

    <joint name="world__base" type="fixed">
      <parent link="world"/>
      <child link="base"/>
    </joint>

    <joint name="griper_arm_left_joint" type="revolute">
      <origin xyz="0.00253 0.03151 0.03487" rpy="0 1.5708 0"/>
      <parent link="griper_base"/>
      <child link="griper_arm_left"/>
      <axis xyz="0 0 1.0"/>
      <limit lower="-1.3" upper="0" effort="1.0" velocity="1.0"/>
    </joint>

    <joint name="griper_arm_right_joint" type="revolute">
      <origin xyz="0.00249 -0.0379 0.03487" rpy="3.14159 -1.5708 0"/>
      <parent link="griper_base"/>
      <child link="griper_arm_right"/>
      <axis xyz="0 0 1.0"/>
      <limit lower="-1.3" upper="0" effort="1.0" velocity="1.0"/>
    </joint>

    <joint name="griper_base_joint" type="fixed">
      <origin xyz="-0.00178 -8e-05 0.08506" rpy="0 0 0"/>
      <parent link="link_6"/>
      <child link="griper_base"/>
    </joint>

    <joint name="link_1_joint" type="continuous">
      <origin xyz="0.00201 0.062 1.06632" rpy="0 0 0"/>
      <parent link="base"/>
      <child link="link_1"/>
      <axis xyz="0 0 1.0"/>
      <limit effort="1.0" velocity="1.0"/>
    </joint>

    <joint name="link_2_joint" type="revolute">
      <origin xyz="-0.00201 -0.62635 0.52697" rpy="1.5708 0 0"/>
      <parent link="link_1"/>
      <child link="link_2"/>
      <axis xyz="0 0 1.0"/>
      <limit lower="-1.57" upper="1.57" effort="1.0" velocity="1.0"/>
    </joint>

    <joint name="link_3_joint" type="revolute">
      <origin xyz="0 2.47971 -1.1168" rpy="0 -3.14159 0"/>
      <parent link="link_2"/>
      <child link="link_3"/>
      <axis xyz="0 0 1.0"/>
      <limit lower="-2.57" upper="2.57" effort="1.0" velocity="1.0"/>
    </joint>

    <joint name="link_4_joint" type="continuous">
      <origin xyz="0 2.13791 0.0022" rpy="1.5708 0 -3.14159"/>
      <parent link="link_3"/>
      <child link="link_4"/>
      <axis xyz="0 0 1.0"/>
      <limit effort="1.0" velocity="1.0"/>
    </joint>

    <joint name="link_5_joint" type="revolute">
      <origin xyz="0 8e-05 0.37283" rpy="1.5708 0 0"/>
      <parent link="link_4"/>
      <child link="link_5"/>
      <axis xyz="0 0 1.0"/>
      <limit lower="-1.57" upper="1.57" effort="1.0" velocity="1.0"/>
    </joint>

    <joint name="link_6_joint" type="continuous">
      <origin xyz="0 1.03991 0" rpy="-1.5708 0 0"/>
      <parent link="link_5"/>
      <child link="link_6"/>
      <axis xyz="0 0 1.0"/>
      <limit effort="1.0" velocity="1.0"/>
    </joint>

    <material name="base_material">
      <color rgba="0.00293 0.17898 0.64 1.0"/>
    </material>

    <material name="griper_material">
      <color rgba="0 0.62196 0.64 1.0"/>
    </material>

    <material name="link_1_material">
      <color rgba="0.27804 0.56837 0.64 1.0"/>
    </material>

    <material name="link_2_material">
      <color rgba="0.03587 0.64 0.15975 1.0"/>
    </material>

    <material name="link_3_material">
      <color rgba="0.64 0.12974 0.1869 1.0"/>
    </material>

    <material name="link_4_material">
      <color rgba="0.63358 0.64 0.05655 1.0"/>
    </material>

    <material name="link_5_material">
      <color rgba="0.64 0.13903 0.59154 1.0"/>
    </material>

    <material name="link_6_material">
      <color rgba="0.27033 0.06955 0.64 1.0"/>
    </material>

  </robot>
