<?xml version="1.0"?>
<!-- created with Phobos 1.0.1 "Capricious Choutengan" -->
  <robot name="arm_scale">

    <link name="world"/>

    <link name="base">
      <inertial>
        <origin xyz="0 0 -1.74435" rpy="0 0 0"/>
        <mass value="1.0"/>
        <inertia ixx="58.83333" ixy="0" ixz="0" iyy="58.83333" iyz="0" izz="104.16666"/>
      </inertial>
      <visual name="base">
        <origin xyz="0 0 0" rpy="0 0 0"/>
        <geometry>
          <mesh filename="package://model_spawner/model/arm8/meshes/dae/base_mesh.dae" scale="12.5 12.5 4.5"/>
        </geometry>
        <material name="base_material"/>
      </visual>
      <collision name="base">
        <origin xyz="0 0 -1.74435" rpy="0 0 0"/>
        <geometry>
          <box size="25.0 25.0 9.0"/>
        </geometry>
      </collision>
    </link>

    <link name="griper_arm_left">
      <inertial>
        <origin xyz="-5.78306 2.02517 0" rpy="0 0 0"/>
        <mass value="1.0"/>
        <inertia ixx="9.98334" ixy="-1e-05" ixz="0" iyy="11.26601" iyz="-3e-05" izz="3.20532"/>
      </inertial>
      <visual name="griper_arm_left">
        <origin xyz="-5.54787 1.76019 0" rpy="0 -1.5708 0"/>
        <geometry>
          <mesh filename="package://model_spawner/model/arm8/meshes/dae/griper_arm_left_mesh.dae" scale="5.60444 5.60444 1.40111"/>
        </geometry>
        <material name="griper_material"/>
      </visual>
      <collision name="griper_arm_left">
        <origin xyz="-5.78307 2.02517 0" rpy="0 -1.5708 0"/>
        <geometry>
          <box size="5.18921 3.39646 10.40501"/>
        </geometry>
      </collision>
    </link>

    <link name="griper_arm_right">
      <inertial>
        <origin xyz="5.78311 2.02294 0.00036" rpy="0 0 0"/>
        <mass value="1.0"/>
        <inertia ixx="9.9175" ixy="-3e-05" ixz="0" iyy="11.20285" iyz="0" izz="3.20262"/>
      </inertial>
      <visual name="griper_arm_right">
        <origin xyz="5.5479 1.75795 0.00036" rpy="0 1.5708 0"/>
        <geometry>
          <mesh filename="package://model_spawner/model/arm8/meshes/dae/griper_arm_right_mesh.dae" scale="5.60444 5.60444 1.40111"/>
        </geometry>
        <material name="griper_material"/>
      </visual>
      <collision name="griper_arm_right">
        <origin xyz="5.78312 2.02294 0.00036" rpy="0 1.5708 0"/>
        <geometry>
          <box size="5.18921 3.39169 10.36853"/>
        </geometry>
      </collision>
    </link>

    <link name="griper_base">
      <inertial>
        <origin xyz="0 0 0" rpy="0 0 0"/>
        <mass value="1.0"/>
        <inertia ixx="0.34773" ixy="0" ixz="0" iyy="1.48113" iyz="0" izz="1.75487"/>
      </inertial>
      <visual name="griper_base">
        <origin xyz="0 0 0" rpy="0 0 0"/>
        <geometry>
          <mesh filename="package://model_spawner/model/arm8/meshes/dae/griper_base_mesh.dae" scale="2.08144 0.9655 0.52036"/>
        </geometry>
        <material name="griper_material"/>
      </visual>
      <collision name="griper_base">
        <origin xyz="0 0 0" rpy="0 0 0"/>
        <geometry>
          <box size="4.16289 1.931 0.66633"/>
        </geometry>
      </collision>
    </link>

    <link name="link_1">
      <inertial>
        <origin xyz="-0.02008 -0.61999 0.72337" rpy="0 0 0"/>
        <mass value="1.0"/>
        <inertia ixx="37.3799" ixy="0" ixz="0" iyy="37.3799" iyz="0" izz="66.66666"/>
      </inertial>
      <visual name="link_1">
        <origin xyz="0 0 0" rpy="0 0 0"/>
        <geometry>
          <mesh filename="package://model_spawner/model/arm8/meshes/dae/link_1_mesh.dae" scale="10.0 10.0 3.5"/>
        </geometry>
        <material name="link_1_material"/>
      </visual>
      <collision name="link_1">
        <origin xyz="-0.02008 -0.61999 0.72337" rpy="0 0 0"/>
        <geometry>
          <box size="20.0 20.0 6.96841"/>
        </geometry>
      </collision>
    </link>

    <link name="link_2">
      <inertial>
        <origin xyz="0 12.4999 -0.56251" rpy="0 0 0"/>
        <mass value="1.0"/>
        <inertia ixx="81.01183" ixy="0" ixz="0" iyy="79.44607" iyz="-2e-05" izz="15.06576"/>
      </inertial>
      <visual name="link_2">
        <origin xyz="0 12.49996 0" rpy="0 0 0"/>
        <geometry>
          <mesh filename="package://model_spawner/model/arm8/meshes/dae/link_2_mesh.dae" scale="4.0 4.0 4.0"/>
        </geometry>
        <material name="link_2_material"/>
      </visual>
      <collision name="link_2">
        <origin xyz="0 12.4999 -0.56251" rpy="0 0 0"/>
        <geometry>
          <box size="9.0 29.53562 9.98945"/>
        </geometry>
      </collision>
    </link>

    <link name="link_3">
      <inertial>
        <origin xyz="0 4.16669 -0.56363" rpy="0 0 0"/>
        <mass value="1.0"/>
        <inertia ixx="32.19439" ixy="0" ixz="0" iyy="30.62864" iyz="0" izz="15.06575"/>
      </inertial>
      <visual name="link_3">
        <origin xyz="0 2e-05 0" rpy="0 0 0"/>
        <geometry>
          <mesh filename="package://model_spawner/model/arm8/meshes/dae/link_3_mesh.dae" scale="4.0 4.0 4.0"/>
        </geometry>
        <material name="link_3_material"/>
      </visual>
      <collision name="link_3">
        <origin xyz="0 4.16669 -0.56363" rpy="0 0 0"/>
        <geometry>
          <box size="9.0 16.9276 9.98945"/>
        </geometry>
      </collision>
    </link>

    <link name="link_4">
      <inertial>
        <origin xyz="0 0 -0.40428" rpy="0 0 0"/>
        <mass value="1.0"/>
        <inertia ixx="11.16848" ixy="0" ixz="0" iyy="11.16848" iyz="0" izz="10.66669"/>
      </inertial>
      <visual name="link_4">
        <origin xyz="0 0 -5e-05" rpy="0 0 0"/>
        <geometry>
          <mesh filename="package://model_spawner/model/arm8/meshes/dae/link_4_mesh.dae" scale="4.0 4.0 6.25"/>
        </geometry>
        <material name="link_4_material"/>
      </visual>
      <collision name="link_4">
        <origin xyz="0 0 -0.40428" rpy="0 0 0"/>
        <geometry>
          <box size="8.0 8.0 8.3679"/>
        </geometry>
      </collision>
    </link>

    <link name="link_5">
      <inertial>
        <origin xyz="0 3.11311 0.00078" rpy="0 0 0"/>
        <mass value="1.0"/>
        <inertia ixx="7.9991" ixy="0" ixz="0" iyy="7.9991" iyz="0" izz="10.66668"/>
      </inertial>
      <visual name="link_5">
        <origin xyz="0 3.6415 0" rpy="-1.5708 0 0"/>
        <geometry>
          <mesh filename="package://model_spawner/model/arm8/meshes/dae/link_5_mesh.dae" scale="4.0 4.0 4.0"/>
        </geometry>
        <material name="link_5_material"/>
      </visual>
      <collision name="link_5">
        <origin xyz="0 3.1131 0.00078" rpy="-1.5708 0 0"/>
        <geometry>
          <box size="8.0 8.0 5.65589"/>
        </geometry>
      </collision>
    </link>

    <link name="link_6">
      <inertial>
        <origin xyz="0 0 0.09017" rpy="0 0 0"/>
        <mass value="1.0"/>
        <inertia ixx="5.37206" ixy="0" ixz="0" iyy="5.37207" iyz="-3e-05" izz="10.66668"/>
      </inertial>
      <visual name="link_6">
        <origin xyz="0 0 0.74929" rpy="0 0 0"/>
        <geometry>
          <mesh filename="package://model_spawner/model/arm8/meshes/dae/link_6_mesh.dae" scale="4.0 4.0 1.0"/>
        </geometry>
        <material name="link_6_material"/>
      </visual>
      <collision name="link_6">
        <origin xyz="0 0 0.09017" rpy="0 0 0"/>
        <geometry>
          <box size="8.0 8.0 0.68176"/>
        </geometry>
      </collision>
    </link>

    <joint name="world__base" type="fixed">
      <parent link="world"/>
      <child link="base"/>
    </joint>

    <joint name="griper_arm_left_joint" type="revolute">
      <origin xyz="0.02528 0.31512 0.34874" rpy="0 1.5708 0"/>
      <parent link="griper_base"/>
      <child link="griper_arm_left"/>
      <axis xyz="0 0 1.0"/>
      <limit lower="-1.3" upper="0" effort="1.0" velocity="1.0"/>
    </joint>

    <joint name="griper_arm_right_joint" type="revolute">
      <origin xyz="0.02492 -0.37903 0.34874" rpy="3.14159 -1.5708 0"/>
      <parent link="griper_base"/>
      <child link="griper_arm_right"/>
      <axis xyz="0 0 1.0"/>
      <limit lower="-1.3" upper="0" effort="1.0" velocity="1.0"/>
    </joint>

    <joint name="griper_base_joint" type="fixed">
      <origin xyz="-0.01779 -0.00082 0.85057" rpy="0 0 0"/>
      <parent link="link_6"/>
      <child link="griper_base"/>
    </joint>

    <joint name="link_1_joint" type="continuous">
      <origin xyz="0.02008 0.61999 10.66318" rpy="0 0 0"/>
      <parent link="base"/>
      <child link="link_1"/>
      <axis xyz="0 0 1.0"/>
      <limit effort="1.0" velocity="1.0"/>
    </joint>

    <joint name="link_2_joint" type="fixed">
      <origin xyz="-0.02008 -6.26349 5.2697" rpy="1.5708 0 0"/>
      <parent link="link_1"/>
      <child link="link_2"/>
      <limit effort="0" velocity="0"/>
    </joint>

    <joint name="link_3_joint" type="revolute">
      <origin xyz="0 24.7971 -11.16805" rpy="0 -3.14159 0"/>
      <parent link="link_2"/>
      <child link="link_3"/>
      <axis xyz="0 0 1.0"/>
      <limit lower="-2.57" upper="2.57" effort="1.0" velocity="1.0"/>
    </joint>

    <joint name="link_4_joint" type="continuous">
      <origin xyz="0 21.37913 0.02204" rpy="1.5708 0 -3.14159"/>
      <parent link="link_3"/>
      <child link="link_4"/>
      <axis xyz="0 0 1.0"/>
      <limit effort="1.0" velocity="1.0"/>
    </joint>

    <joint name="link_5_joint" type="revolute">
      <origin xyz="0 0.00078 3.72826" rpy="1.5708 0 0"/>
      <parent link="link_4"/>
      <child link="link_5"/>
      <axis xyz="0 0 1.0"/>
      <limit lower="-1.57" upper="1.57" effort="1.0" velocity="1.0"/>
    </joint>

    <joint name="link_6_joint" type="continuous">
      <origin xyz="0 10.39911 0" rpy="-1.5708 0 0"/>
      <parent link="link_5"/>
      <child link="link_6"/>
      <axis xyz="0 0 1.0"/>
      <limit effort="1.0" velocity="1.0"/>
    </joint>

    <material name="base_material">
      <color rgba="0.00293 0.17898 0.64 1.0"/>
    </material>

    <material name="griper_material">
      <color rgba="0 0.62196 0.64 1.0"/>
    </material>

    <material name="link_1_material">
      <color rgba="0.27804 0.56837 0.64 1.0"/>
    </material>

    <material name="link_2_material">
      <color rgba="0.03587 0.64 0.15975 1.0"/>
    </material>

    <material name="link_3_material">
      <color rgba="0.64 0.12974 0.1869 1.0"/>
    </material>

    <material name="link_4_material">
      <color rgba="0.63358 0.64 0.05655 1.0"/>
    </material>

    <material name="link_5_material">
      <color rgba="0.64 0.13903 0.59154 1.0"/>
    </material>

    <material name="link_6_material">
      <color rgba="0.27033 0.06955 0.64 1.0"/>
    </material>

  </robot>
